<?xml version="1.0"?>
<!-- =================================================================================== -->
<!-- |    This document was autogenerated by xacro from robot.xacro                    | -->
<!-- |    EDITING THIS FILE BY HAND IS NOT RECOMMENDED                                 | -->
<!-- =================================================================================== -->

<robot xmlns:xacro="http://ros.org/wiki/xacro">
    <xacro:macro name="a6x_robot">
        <link name="base_link">
            <visual>
                <geometry>
                <mesh filename="package://a6x_description/meshes/visual/base_link.STL" />
                </geometry>
                <origin xyz="0.000 0.000 0.000" rpy="0.000 0.000 0.000" />
                <material name="aquablue" >
                    <color rgba="0.00784313725490196 0.8470588235294118 0.9137254901960784 1.0" />
                </material>
            </visual>
            <collision>
                <geometry>
                <mesh filename="package://a6x_description/meshes/visual/base_link.STL" />
                </geometry>
                <origin xyz="0.000 0.000 0.000" rpy="0.000 0.000 0.000" />
            </collision>
            <inertial>
                <mass value="2.020908" />
                <origin xyz="0.010364 -0.013298 0.019441" rpy="0 0 0" />
                <inertia ixx="0.007042" ixy="-0.000717" ixz="-0.000018" 
                        iyy="0.003221" iyz="0.000166" 
                        izz="0.009183" />
            </inertial>
        </link>

        <joint name="shoulder_yaw_joint" type="revolute">
            <parent link="base_link" />
            <child link="shoulder_link" />
            <origin xyz="0.000 0.000 0.063" rpy="0 0 0" />
            <axis xyz="0 0 1" />
            <limit lower="-3.14" upper="3.14" effort="10" velocity="1.0" />
        </joint>

        <link name="shoulder_link">
            <visual>
                <geometry>
                <mesh filename="package://a6x_description/meshes/visual/shoulder_link.STL" />
                </geometry>
                <origin xyz="0.000 0.000 0.000" rpy="0.000 0.000 0.000" />
                <material name="aquablue" >
                    <color rgba="0.00784313725490196 0.8470588235294118 0.9137254901960784 1.0" />
                </material>
            </visual>
            <collision>
                <geometry>
                <mesh filename="package://a6x_description/meshes/visual/shoulder_link.STL" />
                </geometry>
                <origin xyz="0.000 0.000 0.000" rpy="0.000 0.000 0.000" />
            </collision>
            <inertial>
                <mass value="0.367611" />
                <origin xyz="0.000000 -0.000082 0.019648" rpy="0 0 0" />
                <inertia ixx="0.000415" ixy="0.000000" ixz="0.000000" 
                        iyy="0.000537" iyz="-0.000001" 
                        izz="0.000645" />
            </inertial>
        </link>

        <joint name="arm_roll_joint" type="revolute">
            <parent link="shoulder_link" />
            <child link="arm_link" />
            <origin xyz="-0.037 0.000 0.060" rpy="0 0 0" />
            <axis xyz="-1 0 0" />
            <limit lower="-2.967" upper="0.785" effort="10" velocity="1.0" />
        </joint>

        <link name="arm_link">
            <visual>
                <geometry>
                <mesh filename="package://a6x_description/meshes/visual/arm_link.STL" />
                </geometry>
                <origin xyz="0.000 0.000 0.000" rpy="0.000 0.000 0.000" />
                <material name="aquablue" >
                    <color rgba="0.00784313725490196 0.8470588235294118 0.9137254901960784 1.0" />
                </material>
            </visual>
            <collision>
                <geometry>
                <mesh filename="package://a6x_description/meshes/visual/arm_link.STL" />
                </geometry>
                <origin xyz="0.000 0.000 0.000" rpy="0.000 0.000 0.000" />
            </collision>
            <inertial>
                <mass value="1.783675" />
                <origin xyz="0.035891 -0.069538 0.028493" rpy="0 0 0" />
                <inertia ixx="0.027167" ixy="-0.000287" ixz="0.000116" 
                        iyy="0.007550" iyz="-0.009088" 
                        izz="0.026001" />
            </inertial>
        </link>
    </xacro:macro>
</robot>
